{
 "cells": [
  {
   "cell_type": "code",
   "execution_count": 6,
   "id": "55d14583-f8be-4fdd-93cc-b1f3fa93ca08",
   "metadata": {},
   "outputs": [],
   "source": [
    "import pymysql.cursors\n"
   ]
  },
  {
   "cell_type": "code",
   "execution_count": 13,
   "id": "76d8fcf0-d9b2-49dc-b7a6-13cf82aa8665",
   "metadata": {},
   "outputs": [],
   "source": [
    "db = pymysql.connect(db=\"db_datamanagement\", user=\"dian\", passwd=\"loginDMS!@#\",host=\"103.142.111.56\",port=53246,autocommit=True)"
   ]
  },
  {
   "cell_type": "code",
   "execution_count": 9,
   "id": "14b0ab02-a942-4cf9-bf2b-36a5b04a6b28",
   "metadata": {},
   "outputs": [
    {
     "name": "stdout",
     "output_type": "stream",
     "text": [
      "Database version : 5.7.35-log \n"
     ]
    }
   ],
   "source": [
    "cursor = db.cursor()\n",
    "cursor.execute(\"SELECT VERSION()\")\n",
    "data = cursor.fetchone()\n",
    "print (\"Database version : %s \" % data)\n",
    "db.close()"
   ]
  },
  {
   "cell_type": "code",
   "execution_count": 14,
   "id": "996803f9-2ec5-4d21-9cd9-ffca85f06f7a",
   "metadata": {},
   "outputs": [],
   "source": [
    "cursor=db.cursor()\n",
    "cursor.execute(\"select * from mra_temp\")\n",
    "data = cursor.fetchall()\n",
    "db.close()"
   ]
  },
  {
   "cell_type": "code",
   "execution_count": null,
   "id": "8020999a-fc9c-46f5-a733-48c53c10d6d3",
   "metadata": {},
   "outputs": [
    {
     "name": "stderr",
     "output_type": "stream",
     "text": [
      "ERROR:root:Internal Python error in the inspect module.\n",
      "Below is the traceback from this internal error.\n",
      "\n",
      "ERROR:root:Internal Python error in the inspect module.\n",
      "Below is the traceback from this internal error.\n",
      "\n",
      "ERROR:root:Internal Python error in the inspect module.\n",
      "Below is the traceback from this internal error.\n",
      "\n"
     ]
    },
    {
     "name": "stdout",
     "output_type": "stream",
     "text": [
      "Traceback (most recent call last):\n",
      "  File \"/Users/dianarisona/opt/anaconda3/lib/python3.9/site-packages/IPython/core/interactiveshell.py\", line 3444, in run_code\n",
      "    exec(code_obj, self.user_global_ns, self.user_ns)\n",
      "  File \"/var/folders/67/5wjhzv7x1vggxtnh5tn1f2z80000gp/T/ipykernel_52542/2768961113.py\", line 1, in <module>\n",
      "    import pandas\n",
      "  File \"<frozen importlib._bootstrap>\", line 1007, in _find_and_load\n",
      "  File \"<frozen importlib._bootstrap>\", line 982, in _find_and_load_unlocked\n",
      "  File \"<frozen importlib._bootstrap>\", line 925, in _find_spec\n",
      "  File \"<frozen importlib._bootstrap_external>\", line 1414, in find_spec\n",
      "  File \"<frozen importlib._bootstrap_external>\", line 1383, in _get_spec\n",
      "  File \"<frozen importlib._bootstrap_external>\", line 1347, in _path_importer_cache\n",
      "PermissionError: [Errno 1] Operation not permitted\n",
      "\n",
      "During handling of the above exception, another exception occurred:\n",
      "\n",
      "Traceback (most recent call last):\n",
      "  File \"/Users/dianarisona/opt/anaconda3/lib/python3.9/site-packages/IPython/core/interactiveshell.py\", line 2064, in showtraceback\n",
      "    stb = value._render_traceback_()\n",
      "AttributeError: 'PermissionError' object has no attribute '_render_traceback_'\n",
      "\n",
      "During handling of the above exception, another exception occurred:\n",
      "\n",
      "Traceback (most recent call last):\n",
      "  File \"/Users/dianarisona/opt/anaconda3/lib/python3.9/site-packages/IPython/core/ultratb.py\", line 1101, in get_records\n",
      "    return _fixed_getinnerframes(etb, number_of_lines_of_context, tb_offset)\n",
      "  File \"/Users/dianarisona/opt/anaconda3/lib/python3.9/site-packages/IPython/core/ultratb.py\", line 248, in wrapped\n",
      "    return f(*args, **kwargs)\n",
      "  File \"/Users/dianarisona/opt/anaconda3/lib/python3.9/site-packages/IPython/core/ultratb.py\", line 281, in _fixed_getinnerframes\n",
      "    records = fix_frame_records_filenames(inspect.getinnerframes(etb, context))\n",
      "  File \"/Users/dianarisona/opt/anaconda3/lib/python3.9/inspect.py\", line 1541, in getinnerframes\n",
      "    frameinfo = (tb.tb_frame,) + getframeinfo(tb, context)\n",
      "  File \"/Users/dianarisona/opt/anaconda3/lib/python3.9/inspect.py\", line 1499, in getframeinfo\n",
      "    filename = getsourcefile(frame) or getfile(frame)\n",
      "  File \"/Users/dianarisona/opt/anaconda3/lib/python3.9/inspect.py\", line 709, in getsourcefile\n",
      "    if getattr(getmodule(object, filename), '__loader__', None) is not None:\n",
      "  File \"/Users/dianarisona/opt/anaconda3/lib/python3.9/inspect.py\", line 738, in getmodule\n",
      "    file = getabsfile(object, _filename)\n",
      "  File \"/Users/dianarisona/opt/anaconda3/lib/python3.9/inspect.py\", line 722, in getabsfile\n",
      "    return os.path.normcase(os.path.abspath(_filename))\n",
      "  File \"/Users/dianarisona/opt/anaconda3/lib/python3.9/posixpath.py\", line 380, in abspath\n",
      "    cwd = os.getcwd()\n",
      "PermissionError: [Errno 1] Operation not permitted\n",
      "Traceback (most recent call last):\n",
      "  File \"/Users/dianarisona/opt/anaconda3/lib/python3.9/site-packages/IPython/core/interactiveshell.py\", line 3444, in run_code\n",
      "    exec(code_obj, self.user_global_ns, self.user_ns)\n",
      "  File \"/var/folders/67/5wjhzv7x1vggxtnh5tn1f2z80000gp/T/ipykernel_52542/2768961113.py\", line 1, in <module>\n",
      "    import pandas\n",
      "  File \"<frozen importlib._bootstrap>\", line 1007, in _find_and_load\n",
      "  File \"<frozen importlib._bootstrap>\", line 982, in _find_and_load_unlocked\n",
      "  File \"<frozen importlib._bootstrap>\", line 925, in _find_spec\n",
      "  File \"<frozen importlib._bootstrap_external>\", line 1414, in find_spec\n",
      "  File \"<frozen importlib._bootstrap_external>\", line 1383, in _get_spec\n",
      "  File \"<frozen importlib._bootstrap_external>\", line 1347, in _path_importer_cache\n",
      "PermissionError: [Errno 1] Operation not permitted\n",
      "\n",
      "During handling of the above exception, another exception occurred:\n",
      "\n",
      "Traceback (most recent call last):\n",
      "  File \"/Users/dianarisona/opt/anaconda3/lib/python3.9/site-packages/IPython/core/interactiveshell.py\", line 2064, in showtraceback\n",
      "    stb = value._render_traceback_()\n",
      "AttributeError: 'PermissionError' object has no attribute '_render_traceback_'\n",
      "\n",
      "During handling of the above exception, another exception occurred:\n",
      "\n",
      "Traceback (most recent call last):\n",
      "  File \"/Users/dianarisona/opt/anaconda3/lib/python3.9/site-packages/IPython/core/interactiveshell.py\", line 3364, in run_ast_nodes\n",
      "    if (await self.run_code(code, result,  async_=asy)):\n",
      "  File \"/Users/dianarisona/opt/anaconda3/lib/python3.9/site-packages/IPython/core/interactiveshell.py\", line 3461, in run_code\n",
      "    self.showtraceback(running_compiled_code=True)\n",
      "  File \"/Users/dianarisona/opt/anaconda3/lib/python3.9/site-packages/IPython/core/interactiveshell.py\", line 2066, in showtraceback\n",
      "    stb = self.InteractiveTB.structured_traceback(etype,\n",
      "  File \"/Users/dianarisona/opt/anaconda3/lib/python3.9/site-packages/IPython/core/ultratb.py\", line 1367, in structured_traceback\n",
      "    return FormattedTB.structured_traceback(\n",
      "  File \"/Users/dianarisona/opt/anaconda3/lib/python3.9/site-packages/IPython/core/ultratb.py\", line 1267, in structured_traceback\n",
      "    return VerboseTB.structured_traceback(\n",
      "  File \"/Users/dianarisona/opt/anaconda3/lib/python3.9/site-packages/IPython/core/ultratb.py\", line 1124, in structured_traceback\n",
      "    formatted_exception = self.format_exception_as_a_whole(etype, evalue, etb, number_of_lines_of_context,\n",
      "  File \"/Users/dianarisona/opt/anaconda3/lib/python3.9/site-packages/IPython/core/ultratb.py\", line 1082, in format_exception_as_a_whole\n",
      "    last_unique, recursion_repeat = find_recursion(orig_etype, evalue, records)\n",
      "  File \"/Users/dianarisona/opt/anaconda3/lib/python3.9/site-packages/IPython/core/ultratb.py\", line 382, in find_recursion\n",
      "    return len(records), 0\n",
      "TypeError: object of type 'NoneType' has no len()\n",
      "\n",
      "During handling of the above exception, another exception occurred:\n",
      "\n",
      "Traceback (most recent call last):\n",
      "  File \"/Users/dianarisona/opt/anaconda3/lib/python3.9/site-packages/IPython/core/interactiveshell.py\", line 2064, in showtraceback\n",
      "    stb = value._render_traceback_()\n",
      "AttributeError: 'TypeError' object has no attribute '_render_traceback_'\n",
      "\n",
      "During handling of the above exception, another exception occurred:\n",
      "\n",
      "Traceback (most recent call last):\n",
      "  File \"/Users/dianarisona/opt/anaconda3/lib/python3.9/site-packages/IPython/core/ultratb.py\", line 1101, in get_records\n",
      "    return _fixed_getinnerframes(etb, number_of_lines_of_context, tb_offset)\n",
      "  File \"/Users/dianarisona/opt/anaconda3/lib/python3.9/site-packages/IPython/core/ultratb.py\", line 248, in wrapped\n",
      "    return f(*args, **kwargs)\n",
      "  File \"/Users/dianarisona/opt/anaconda3/lib/python3.9/site-packages/IPython/core/ultratb.py\", line 281, in _fixed_getinnerframes\n",
      "    records = fix_frame_records_filenames(inspect.getinnerframes(etb, context))\n",
      "  File \"/Users/dianarisona/opt/anaconda3/lib/python3.9/inspect.py\", line 1541, in getinnerframes\n",
      "    frameinfo = (tb.tb_frame,) + getframeinfo(tb, context)\n",
      "  File \"/Users/dianarisona/opt/anaconda3/lib/python3.9/inspect.py\", line 1499, in getframeinfo\n",
      "    filename = getsourcefile(frame) or getfile(frame)\n",
      "  File \"/Users/dianarisona/opt/anaconda3/lib/python3.9/inspect.py\", line 709, in getsourcefile\n",
      "    if getattr(getmodule(object, filename), '__loader__', None) is not None:\n",
      "  File \"/Users/dianarisona/opt/anaconda3/lib/python3.9/inspect.py\", line 738, in getmodule\n",
      "    file = getabsfile(object, _filename)\n",
      "  File \"/Users/dianarisona/opt/anaconda3/lib/python3.9/inspect.py\", line 722, in getabsfile\n",
      "    return os.path.normcase(os.path.abspath(_filename))\n",
      "  File \"/Users/dianarisona/opt/anaconda3/lib/python3.9/posixpath.py\", line 380, in abspath\n",
      "    cwd = os.getcwd()\n",
      "PermissionError: [Errno 1] Operation not permitted\n",
      "Traceback (most recent call last):\n",
      "  File \"/Users/dianarisona/opt/anaconda3/lib/python3.9/site-packages/IPython/core/interactiveshell.py\", line 3444, in run_code\n",
      "    exec(code_obj, self.user_global_ns, self.user_ns)\n",
      "  File \"/var/folders/67/5wjhzv7x1vggxtnh5tn1f2z80000gp/T/ipykernel_52542/2768961113.py\", line 1, in <module>\n",
      "    import pandas\n",
      "  File \"<frozen importlib._bootstrap>\", line 1007, in _find_and_load\n",
      "  File \"<frozen importlib._bootstrap>\", line 982, in _find_and_load_unlocked\n",
      "  File \"<frozen importlib._bootstrap>\", line 925, in _find_spec\n",
      "  File \"<frozen importlib._bootstrap_external>\", line 1414, in find_spec\n",
      "  File \"<frozen importlib._bootstrap_external>\", line 1383, in _get_spec\n",
      "  File \"<frozen importlib._bootstrap_external>\", line 1347, in _path_importer_cache\n",
      "PermissionError: [Errno 1] Operation not permitted\n",
      "\n",
      "During handling of the above exception, another exception occurred:\n",
      "\n",
      "Traceback (most recent call last):\n",
      "  File \"/Users/dianarisona/opt/anaconda3/lib/python3.9/site-packages/IPython/core/interactiveshell.py\", line 2064, in showtraceback\n",
      "    stb = value._render_traceback_()\n",
      "AttributeError: 'PermissionError' object has no attribute '_render_traceback_'\n",
      "\n",
      "During handling of the above exception, another exception occurred:\n",
      "\n",
      "Traceback (most recent call last):\n",
      "  File \"/Users/dianarisona/opt/anaconda3/lib/python3.9/site-packages/IPython/core/interactiveshell.py\", line 3364, in run_ast_nodes\n",
      "    if (await self.run_code(code, result,  async_=asy)):\n",
      "  File \"/Users/dianarisona/opt/anaconda3/lib/python3.9/site-packages/IPython/core/interactiveshell.py\", line 3461, in run_code\n",
      "    self.showtraceback(running_compiled_code=True)\n",
      "  File \"/Users/dianarisona/opt/anaconda3/lib/python3.9/site-packages/IPython/core/interactiveshell.py\", line 2066, in showtraceback\n",
      "    stb = self.InteractiveTB.structured_traceback(etype,\n",
      "  File \"/Users/dianarisona/opt/anaconda3/lib/python3.9/site-packages/IPython/core/ultratb.py\", line 1367, in structured_traceback\n",
      "    return FormattedTB.structured_traceback(\n",
      "  File \"/Users/dianarisona/opt/anaconda3/lib/python3.9/site-packages/IPython/core/ultratb.py\", line 1267, in structured_traceback\n",
      "    return VerboseTB.structured_traceback(\n",
      "  File \"/Users/dianarisona/opt/anaconda3/lib/python3.9/site-packages/IPython/core/ultratb.py\", line 1124, in structured_traceback\n",
      "    formatted_exception = self.format_exception_as_a_whole(etype, evalue, etb, number_of_lines_of_context,\n",
      "  File \"/Users/dianarisona/opt/anaconda3/lib/python3.9/site-packages/IPython/core/ultratb.py\", line 1082, in format_exception_as_a_whole\n",
      "    last_unique, recursion_repeat = find_recursion(orig_etype, evalue, records)\n",
      "  File \"/Users/dianarisona/opt/anaconda3/lib/python3.9/site-packages/IPython/core/ultratb.py\", line 382, in find_recursion\n",
      "    return len(records), 0\n",
      "TypeError: object of type 'NoneType' has no len()\n",
      "\n",
      "During handling of the above exception, another exception occurred:\n",
      "\n",
      "Traceback (most recent call last):\n",
      "  File \"/Users/dianarisona/opt/anaconda3/lib/python3.9/site-packages/IPython/core/interactiveshell.py\", line 2064, in showtraceback\n",
      "    stb = value._render_traceback_()\n",
      "AttributeError: 'TypeError' object has no attribute '_render_traceback_'\n",
      "\n",
      "During handling of the above exception, another exception occurred:\n",
      "\n",
      "Traceback (most recent call last):\n",
      "  File \"/Users/dianarisona/opt/anaconda3/lib/python3.9/site-packages/IPython/core/interactiveshell.py\", line 2947, in _run_cell\n",
      "    return runner(coro)\n",
      "  File \"/Users/dianarisona/opt/anaconda3/lib/python3.9/site-packages/IPython/core/async_helpers.py\", line 68, in _pseudo_sync_runner\n",
      "    coro.send(None)\n",
      "  File \"/Users/dianarisona/opt/anaconda3/lib/python3.9/site-packages/IPython/core/interactiveshell.py\", line 3172, in run_cell_async\n",
      "    has_raised = await self.run_ast_nodes(code_ast.body, cell_name,\n",
      "  File \"/Users/dianarisona/opt/anaconda3/lib/python3.9/site-packages/IPython/core/interactiveshell.py\", line 3383, in run_ast_nodes\n",
      "    self.showtraceback()\n",
      "  File \"/Users/dianarisona/opt/anaconda3/lib/python3.9/site-packages/IPython/core/interactiveshell.py\", line 2066, in showtraceback\n",
      "    stb = self.InteractiveTB.structured_traceback(etype,\n",
      "  File \"/Users/dianarisona/opt/anaconda3/lib/python3.9/site-packages/IPython/core/ultratb.py\", line 1367, in structured_traceback\n",
      "    return FormattedTB.structured_traceback(\n",
      "  File \"/Users/dianarisona/opt/anaconda3/lib/python3.9/site-packages/IPython/core/ultratb.py\", line 1267, in structured_traceback\n",
      "    return VerboseTB.structured_traceback(\n",
      "  File \"/Users/dianarisona/opt/anaconda3/lib/python3.9/site-packages/IPython/core/ultratb.py\", line 1142, in structured_traceback\n",
      "    formatted_exceptions += self.format_exception_as_a_whole(etype, evalue, etb, lines_of_context,\n",
      "  File \"/Users/dianarisona/opt/anaconda3/lib/python3.9/site-packages/IPython/core/ultratb.py\", line 1082, in format_exception_as_a_whole\n",
      "    last_unique, recursion_repeat = find_recursion(orig_etype, evalue, records)\n",
      "  File \"/Users/dianarisona/opt/anaconda3/lib/python3.9/site-packages/IPython/core/ultratb.py\", line 382, in find_recursion\n",
      "    return len(records), 0\n",
      "TypeError: object of type 'NoneType' has no len()\n",
      "\n",
      "During handling of the above exception, another exception occurred:\n",
      "\n",
      "Traceback (most recent call last):\n",
      "  File \"/Users/dianarisona/opt/anaconda3/lib/python3.9/site-packages/IPython/core/interactiveshell.py\", line 2064, in showtraceback\n",
      "    stb = value._render_traceback_()\n",
      "AttributeError: 'TypeError' object has no attribute '_render_traceback_'\n",
      "\n",
      "During handling of the above exception, another exception occurred:\n",
      "\n",
      "Traceback (most recent call last):\n",
      "  File \"/Users/dianarisona/opt/anaconda3/lib/python3.9/site-packages/IPython/core/ultratb.py\", line 1101, in get_records\n",
      "    return _fixed_getinnerframes(etb, number_of_lines_of_context, tb_offset)\n",
      "  File \"/Users/dianarisona/opt/anaconda3/lib/python3.9/site-packages/IPython/core/ultratb.py\", line 248, in wrapped\n",
      "    return f(*args, **kwargs)\n",
      "  File \"/Users/dianarisona/opt/anaconda3/lib/python3.9/site-packages/IPython/core/ultratb.py\", line 281, in _fixed_getinnerframes\n",
      "    records = fix_frame_records_filenames(inspect.getinnerframes(etb, context))\n",
      "  File \"/Users/dianarisona/opt/anaconda3/lib/python3.9/inspect.py\", line 1541, in getinnerframes\n",
      "    frameinfo = (tb.tb_frame,) + getframeinfo(tb, context)\n",
      "  File \"/Users/dianarisona/opt/anaconda3/lib/python3.9/inspect.py\", line 1499, in getframeinfo\n",
      "    filename = getsourcefile(frame) or getfile(frame)\n",
      "  File \"/Users/dianarisona/opt/anaconda3/lib/python3.9/inspect.py\", line 709, in getsourcefile\n",
      "    if getattr(getmodule(object, filename), '__loader__', None) is not None:\n",
      "  File \"/Users/dianarisona/opt/anaconda3/lib/python3.9/inspect.py\", line 738, in getmodule\n",
      "    file = getabsfile(object, _filename)\n",
      "  File \"/Users/dianarisona/opt/anaconda3/lib/python3.9/inspect.py\", line 722, in getabsfile\n",
      "    return os.path.normcase(os.path.abspath(_filename))\n",
      "  File \"/Users/dianarisona/opt/anaconda3/lib/python3.9/posixpath.py\", line 380, in abspath\n",
      "    cwd = os.getcwd()\n",
      "PermissionError: [Errno 1] Operation not permitted\n"
     ]
    }
   ],
   "source": [
    "import pandas\n",
    "pd.DataFrame(data)"
   ]
  },
  {
   "cell_type": "code",
   "execution_count": null,
   "id": "c983f8f6-29a2-4d6e-8eb9-770d56b80a39",
   "metadata": {},
   "outputs": [],
   "source": []
  }
 ],
 "metadata": {
  "kernelspec": {
   "display_name": "Python 3 (ipykernel)",
   "language": "python",
   "name": "python3"
  },
  "language_info": {
   "codemirror_mode": {
    "name": "ipython",
    "version": 3
   },
   "file_extension": ".py",
   "mimetype": "text/x-python",
   "name": "python",
   "nbconvert_exporter": "python",
   "pygments_lexer": "ipython3",
   "version": "3.9.7"
  },
  "toc-autonumbering": true,
  "toc-showcode": false
 },
 "nbformat": 4,
 "nbformat_minor": 5
}
